Workbook

Sheet Planilha1
A1: Tabela de preços Felinodelia
A3: Cod | B3: Produto | C3: Custo | D3: Atacado | E3: Varejo | F3: mercado livre | G3: facebook | H3: shoppee | I3: tik tok shop
A4: 1 | B4: Aplicador de Comprimidos | C4: 3.07 | D4: 5.14 | E4: =Calculos!E4 -> 8.9 | F4: =Calculos!K4 -> 16.9 | G4: =Calculos!X4 -> 8.9 | H4: =Calculos!P4 -> 14.9 | I4: =Calculos!U4 -> 12.9
A5: 2 | B5: Bolinha de Petiscos Peixe | C5: 3.06 | D5: 5.11 | E5: =Calculos!E5 -> 8.9 | F5: =Calculos!K5 -> 16.9 | G5: =Calculos!X5 -> 8.9 | H5: =Calculos!P5 -> 14.9 | I5: =Calculos!U5 -> 12.9
A6: 3 | B6: Bolinha de Purga | C6: 3.47 | D6: 5.94 | E6: =Calculos!E6 -> 9.9 | F6: =Calculos!K6 -> 17.9 | G6: =Calculos!X6 -> 9.9 | H6: =Calculos!P6 -> 15.9 | I6: =Calculos!U6 -> 12.9
A7: 4 | B7: Brinquedo Rato médio | C7: 2.49 | D7: 3.98 | E7: =Calculos!E7 -> 7.9 | F7: =Calculos!K7 -> 15.9 | G7: =Calculos!X7 -> 7.9 | H7: =Calculos!P7 -> 13.9 | I7: =Calculos!U7 -> 11.9
A8: 5 | B8: Brinquedo Rato articulado | C8: 2.81 | D8: 4.63 | E8: =Calculos!E8 -> 8.9 | F8: =Calculos!K8 -> 16.9 | G8: =Calculos!X8 -> 8.9 | H8: =Calculos!P8 -> 14.9 | I8: =Calculos!U8 -> 11.9
A9: 6 | B9: Chaveiro Clic vaso Gato | C9: 4.73 | D9: 6.97 | E9: =Calculos!E9 -> 12.9 | F9: =Calculos!K9 -> 19.9 | G9: =Calculos!X9 -> 12.9 | H9: =Calculos!P9 -> 17.9 | I9: =Calculos!U9 -> 14.9
A10: 7 | B10: Chaveiro 4 em 1 (NFC, lata, suporte, chaveiro) | C10: 5.6 | D10: 8.7 | E10: =Calculos!E10 -> 14.9 | F10: =Calculos!K10 -> 20.9 | G10: =Calculos!X10 -> 14.9 | H10: =Calculos!P10 -> 19.9 | I10: =Calculos!U10 -> 16.9
A11: 8 | B11: Chaveiro abre lata pet | C11: 2.76 | D11: 4.03 | E11: =Calculos!E11 -> 8.9 | F11: =Calculos!K11 -> 16.9 | G11: =Calculos!X11 -> 8.9 | H11: =Calculos!P11 -> 13.9 | I11: =Calculos!U11 -> 11.9
A12: 9 | B12: Chaveiro Gato Soco Ingles | C12: 3.12 | D12: 4.74 | E12: =Calculos!E12 -> 9.9 | F12: =Calculos!K12 -> 16.9 | G12: =Calculos!X12 -> 9.9 | H12: =Calculos!P12 -> 14.9 | I12: =Calculos!U12 -> 12.9
A13: 10 | B13: Chaveiro Gato Bravo | C13: 2.49 | D13: 3.48 | E13: =Calculos!E13 -> 7.9 | F13: =Calculos!K13 -> 15.9 | G13: =Calculos!X13 -> 7.9 | H13: =Calculos!P13 -> 13.9 | I13: =Calculos!U13 -> 11.9
A14: 11 | B14: Chaveiro Patinha fofa | C14: 2.59 | D14: 3.68 | E14: =Calculos!E14 -> 7.9 | F14: =Calculos!K14 -> 15.9 | G14: =Calculos!X14 -> 7.9 | H14: =Calculos!P14 -> 13.9 | I14: =Calculos!U14 -> 11.9
A15: 12 | B15: Chaveiro Gato Trevo | C15: 3.09 | D15: 4.67 | E15: =Calculos!E15 -> 8.9 | F15: =Calculos!K15 -> 16.9 | G15: =Calculos!X15 -> 8.9 | H15: =Calculos!P15 -> 14.9 | I15: =Calculos!U15 -> 12.9
... A28: 25 | B28: Porta chaves Gatinho Minimalista | C28: 3.98 | D28: 7.27 | E28: =Calculos!E28 -> 15.9 | F28: =Calculos!K28 -> 21.9 | G28: =Calculos!X28 -> 15.9 | H28: =Calculos!P28 -> 20.9 | I28: =Calculos!U28 -> 17.9

Sheet Parametros
A1: Parâmetros de precificação – Felinodelia
A2: Células em azul com fundo amarelo são editáveis; todo o resto é calculado a partir delas. Taxas pesquisadas em out/2026 – confirme na Central do Vendedor de cada plataforma.
A4: GERAL
A5: Margem líquida desejada nos marketplaces (sobre o preço de venda) | B5: 0.2
A6: Imposto sobre a venda (Simples ≈ 4%; MEI = 0%) | B6: 0.04
A7: Embalagem por pedido (R$) | B7: 1
A8: Arredondar preço p/ final ,90? (1 = sim, 0 = não) | B8: 1
A9: Margem líquida desejada no varejo / Facebook (sobre o preço de venda) | B9: 0.5
A10: MERCADO LIVRE (anúncio Clássico)
A11: Comissão (Clássico 10–14%; Premium 15–19%, conforme categoria) | B11: 0.14
A12: Outros custos % sobre a venda (ex.: Mercado Ads) | B12: 0
A13: Outros custos R$ por pedido (ex.: frete pago pelo vendedor) | B13: 0
A14: Faixa de preço | B14: De (R$) | C14: Até (R$) | D14: Comissão % | E14: Custo fixo (R$) | F14: Custo fixo (% do preço)
A15: Abaixo de R$ 12,50 | B15: 0 | C15: 12.5 | D15: =$B$11 -> 0.14 | E15: 0 | F15: 0.5
A16: R$ 12,50 a 28,99 | B16: 12.5 | C16: 29 | D16: =$B$11 -> 0.14 | E16: 6.25 | F16: 0
A17: R$ 29,00 a 49,99 | B17: 29 | C17: 50 | D17: =$B$11 -> 0.14 | E17: 6.5 | F17: 0
A18: R$ 50,00 a 78,99 | B18: 50 | C18: 79 | D18: =$B$11 -> 0.14 | E18: 6.75 | F18: 0
A19: R$ 79,00 ou mais | B19: 79 | C19: 999999 | D19: =$B$11 -> 0.14 | E19: 0 | F19: 0
A21: SHOPEE
A22: Comissão (até R$ 79,99) | B22: 0.2
A23: Outros custos % sobre a venda (ex.: anúncios, cupons) | B23: 0
A24: Outros custos R$ por pedido (CPF paga +R$ 3 por item) | B24: 0
A25: Faixa de preço | B25: De (R$) | C25: Até (R$) | D25: Comissão % | E25: Custo fixo (R$) | F25: Custo fixo (% do preço)
A26: Abaixo de R$ 8,00 | B26: 0 | C26: 8 | D26: =$B$22 -> 0.2 | E26: 0 | F26: 0.5
A27: R$ 8,00 a 79,99 | B27: 8 | C27: 999999 | D27: =$B$22 -> 0.2 | E27: 4 | F27: 0
A29: TIKTOK SHOP (regra vigente desde 15/07/2026)
A30: Outros custos % sobre a venda (programa de frete: até 6%) | B30: 0
A31: Outros custos R$ por pedido | B31: 0
A32: Faixa de preço | B32: De (R$) | C32: Até (R$) | D32: Comissão % | E32: Custo fixo (R$) | F32: Custo fixo (% do preço)
A33: Abaixo de R$ 50,00 | B33: 0 | C33: 50 | D33: 0.1 | E33: 4 | F33: 0
A34: R$ 50,00 ou mais | B34: 50 | C34: 999999 | D34: 0.06 | E34: 6 | F34: 0
A36: FACEBOOK MARKETPLACE (Brasil: sem comissão da plataforma)
A37: Comissão da plataforma | B37: 0
A38: Taxa de recebimento (Pix = 0%; link de cartão ≈ 3–5%) | B38: 0
A39: Outros custos R$ por pedido | B39: 0
A41: FONTES E OBSERVAÇÕES
A42: Mercado Livre: comissão 10–14% (Clássico) e 15–19% (Premium) por categoria; abaixo de R$ 79 há custo fixo por unidade (R$ 6,25 / 6,50 / 6,75 por faixa; 50% do preço se < R$ 12,50). Desde mar/2026 o ML migrou parte disso para custo variável por peso/dimensão – use o simulador do ML para confirmar o valor exato dos seus itens. Abaixo de R$ 79 o frete é pago pelo comprador.
A43: Shopee: 20% de comissão + R$ 4 por item (50% do preço se item < R$ 8) para preços até R$ 79,99. Vendedor CPF paga +R$ 3 por item (lance em B24).
A44: TikTok Shop: desde 15/07/2026, 10% + R$ 4 por item abaixo de R$ 50 e 6% + R$ 6 por item a partir de R$ 50. O programa de frete cobra até 6% do preço (lance em B30).
A45: Facebook Marketplace: no Brasil não cobra taxa (pagamento e entrega são combinados direto com o comprador). Se o frete for cobrado do cliente, não entra no preço.
...

Sheet Calculos
A1: Cálculo detalhado por plataforma (não editar – tudo vem da aba Parametros)
A3: Cod | B3: Produto | C3: Custo | D3: Custo + embalagem | E3: Varejo | F3: ML faixa 1 (candidato) | G3: ML faixa 2 (candidato) | H3: ML faixa 3 (candidato) | I3: ML faixa 4 (candidato) | J3: ML faixa 5 (candidato) | K3: Mercado Livre – preço | L3: ML – lucro (R$) | M3: ML – margem | N3: Shopee faixa 1 | O3: Shopee faixa 2 | P3: Shopee – preço | Q3: Shopee – lucro (R$) | R3: Shopee – margem | S3: TikTok faixa 1 | T3: TikTok faixa 2 | U3: TikTok – preço | V3: TikTok – lucro (R$) | W3: TikTok – margem | X3: Facebook – preço | Y3: Facebook – lucro (R$) | Z3: Facebook – margem
A4: =Planilha1!A4 -> 1 | B4: =Planilha1!B4 -> Aplicador de Comprimidos | C4: =Planilha1!C4 -> 3.07 | D4: =C4+Parametros!$B$7 -> 4.07 | E4: =IF(Parametros!$B$8=1,CEILING(D4/(1-Parametros!$B$9-Parametros!$B$6)+0.1,1)-0.1,ROUNDUP(D4/(1-Parametros!$B$9-Parametros!$B$6),2)) -> 8.9 | F4: =IF((1-Parametros!$D$15-Parametros!$B$12-Parametros!$B$6-Parametros!$B$5-Parametros!$F$15)<=0,1000000000,MAX(Parametros!$B$15,(D4+Parametros!$E$15+Parametros!$B$13)/(1-Parametros!$D$15-Parametros!$B$12-Parametros!$B$6-Parametros!$B$5-Parametros!$F$15))) -> 33.916667 | G4: =IF((1-Parametros!$D$16-Parametros!$B$12-Parametros!$B$6-Parametros!$B$5-Parametros!$F$16)<=0,1000000000,MAX(Parametros!$B$16,(D4+Parametros!$E$16+Parametros!$B$13)/(1-Parametros!$D$16-Parametros!$B$12-Parametros!$B$6-Parametros!$B$5-Parametros!$F$16))) -> 16.645161 | H4: =IF((1-Parametros!$D$17-Parametros!$B$12-Parametros!$B$6-Parametros!$B$5-Parametros!$F$17)<=0,1000000000,MAX(Parametros!$B$17,(D4+Parametros!$E$17+Parametros!$B$13)/(1-Parametros!$D$17-Parametros!$B$12-Parametros!$B$6-Parametros!$B$5-Parametros!$F$17))) -> 29 | I4: =IF((1-Parametros!$D$18-Parametros!$B$12-Parametros!$B$6-Parametros!$B$5-Parametros!$F$18)<=0,1000000000,MAX(Parametros!$B$18,(D4+Parametros!$E$18+Parametros!$B$13)/(1-Parametros!$D$18-Parametros!$B$12-Parametros!$B$6-Parametros!$B$5-Parametros!$F$18))) -> 50 | J4: =IF((1-Parametros!$D$19-Parametros!$B$12-Parametros!$B$6-Parametros!$B$5-Parametros!$F$19)<=0,1000000000,MAX(Parametros!$B$19,(D4+Parametros!$E$19+Parametros!$B$13)/(1-Parametros!$D$19-Parametros!$B$12-Parametros!$B$6-Parametros!$B$5-Parametros!$F$19))) -> 79 | K4: =IF(Parametros!$B$8=1,CEILING(IF(F4<Parametros!$C$15,F4,IF(G4<Parametros!$C$16,G4,IF(H4<Parametros!$C$17,H4,IF(I4<Parametros!$C$18,I4,J4))))+0.1,1)-0.1,ROUNDUP(IF(F4<Parametros!$C$15,F4,IF(G4<Parametros!$C$16,G4,IF(H4<Parametros!$C$17,H4,IF(I4<Parametros!$C$18,I4,J4)))),2)) -> 16.9 | L4: =K4-K4*(INDEX(Parametros!$D$15:$D$19,MATCH(K4,Parametros!$B$15:$B$19,1))+Parametros!$B$12+Parametros!$B$6+INDEX(Parametros!$F$15:$F$19,MATCH(K4,Parametros!$B$15:$B$19,1)))-INDEX(Parametros!$E$15:$E$19,MATCH(K4,Parametros!$B$15:$B$19,1))-Parametros!$B$13-D4 -> 3.538 | M4: =L4/K4 -> 0.20934911 | N4: =IF((1-Parametros!$D$26-Parametros!$B$23-Parametros!$B$6-Parametros!$B$5-Parametros!$F$26)<=0,1000000000,MAX(Parametros!$B$26,(D4+Parametros!$E$26+Parametros!$B$24)/(1-Parametros!$D$26-Parametros!$B$23-Parametros!$B$6-Parametros!$B$5-Parametros!$F$26))) -> 67.833333 | O4: =IF((1-Parametros!$D$27-Parametros!$B$23-Parametros!$B$6-Parametros!$B$5-Parametros!$F$27)<=0,1000000000,MAX(Parametros!$B$27,(D4+Parametros!$E$27+Parametros!$B$24)/(1-Parametros!$D$27-Parametros!$B$23-Parametros!$B$6-Parametros!$B$5-Parametros!$F$27))) -> 14.410714 | P4: =IF(Parametros!$B$8=1,CEILING(IF(N4<Parametros!$C$26,N4,O4)+0.1,1)-0.1,ROUNDUP(IF(N4<Parametros!$C$26,N4,O4),2)) -> 14.9 | Q4: =P4-P4*(INDEX(Parametros!$D$26:$D$27,MATCH(P4,Parametros!$B$26:$B$27,1))+Parametros!$B$23+Parametros!$B$6+INDEX(Parametros!$F$26:$F$27,MATCH(P4,Parametros!$B$26:$B$27,1)))-INDEX(Parametros!$E$26:$E$27,MATCH(P4,Parametros!$B$26:$B$27,1))-Parametros!$B$24-D4 -> 3.254 | R4: =Q4/P4 -> 0.21838926 | S4: =IF((1-Parametros!$D$33-Parametros!$B$30-Parametros!$B$6-Parametros!$B$5-Parametros!$F$33)<=0,1000000000,MAX(Parametros!$B$33,(D4+Parametros!$E$33+Parametros!$B$31)/(1-Parametros!$D$33-Parametros!$B$30-Parametros!$B$6-Parametros!$B$5-Parametros!$F$33))) -> 12.227273 | T4: =IF((1-Parametros!$D$34-Parametros!$B$30-Parametros!$B$6-Parametros!$B$5-Parametros!$F$34)<=0,1000000000,MAX(Parametros!$B$34,(D4+Parametros!$E$34+Parametros!$B$31)/(1-Parametros!$D$34-Parametros!$B$30-Parametros!$B$6-Parametros!$B$5-Parametros!$F$34))) -> 50 | U4: =IF(Parametros!$B$8=1,CEILING(IF(S4<Parametros!$C$33,S4,T4)+0.1,1)-0.1,ROUNDUP(IF(S4<Parametros!$C$33,S4,T4),2)) -> 12.9 | V4: =U4-U4*(INDEX(Parametros!$D$33:$D$34,MATCH(U4,Parametros!$B$33:$B$34,1))+Parametros!$B$30+Parametros!$B$6+INDEX(Parametros!$F$33:$F$34,MATCH(U4,Parametros!$B$33:$B$34,1)))-INDEX(Parametros!$E$33:$E$34,MATCH(U4,Parametros!$B$33:$B$34,1))-Parametros!$B$31-D4 -> 3.024 | W4: =V4/U4 -> 0.2344186 | X4: =IF(Parametros!$B$8=1,CEILING((D4+Parametros!$B$39)/(1-Parametros!$B$37-Parametros!$B$38-Parametros!$B$6-Parametros!$B$9)+0.1,1)-0.1,ROUNDUP((D4+Parametros!$B$39)/(1-Parametros!$B$37-Parametros!$B$38-Parametros!$B$6-Parametros!$B$9),2)) -> 8.9 | Y4: =X4-X4*(Parametros!$B$37+Parametros!$B$38+Parametros!$B$6)-Parametros!$B$39-D4 -> 4.474 | Z4: =Y4/X4 -> 0.50269663
A5: =Planilha1!A5 -> 2 | B5: =Planilha1!B5 -> Bolinha de Petiscos Peixe | C5: =Planilha1!C5 -> 3.06 | D5: =C5+Parametros!$B$7 -> 4.06 | E5: =IF(Parametros!$B$8=1,CEILING(D5/(1-Parametros!$B$9-Parametros!$B$6)+0.1,1)-0.1,ROUNDUP(D5/(1-Parametros!$B$9-Parametros!$B$6),2)) -> 8.9 | F5: =IF((1-Parametros!$D$15-Parametros!$B$12-Parametros!$B$6-Parametros!$B$5-Parametros!$F$15)<=0,1000000000,MAX(Parametros!$B$15,(D5+Parametros!$E$15+Parametros!$B$13)/(1-Parametros!$D$15-Parametros!$B$12-Parametros!$B$6-Parametros!$B$5-Parametros!$F$15))) -> 33.833333 | G5: =IF((1-Parametros!$D$16-Parametros!$B$12-Parametros!$B$6-Parametros!$B$5-Parametros!$F$16)<=0,1000000000,MAX(Parametros!$B$16,(D5+Parametros!$E$16+Parametros!$B$13)/(1-Parametros!$D$16-Parametros!$B$12-Parametros!$B$6-Parametros!$B$5-Parametros!$F$16))) -> 16.629032 | H5: =IF((1-Parametros!$D$17-Parametros!$B$12-Parametros!$B$6-Parametros!$B$5-Parametros!$F$17)<=0,1000000000,MAX(Parametros!$B$17,(D5+Parametros!$E$17+Parametros!$B$13)/(1-Parametros!$D$17-Parametros!$B$12-Parametros!$B$6-Parametros!$B$5-Parametros!$F$17))) -> 29 | I5: =IF((1-Parametros!$D$18-Parametros!$B$12-Parametros!$B$6-Parametros!$B$5-Parametros!$F$18)<=0,1000000000,MAX(Parametros!$B$18,(D5+Parametros!$E$18+Parametros!$B$13)/(1-Parametros!$D$18-Parametros!$B$12-Parametros!$B$6-Parametros!$B$5-Parametros!$F$18))) -> 50 | J5: =IF((1-Parametros!$D$19-Parametros!$B$12-Parametros!$B$6-Parametros!$B$5-Parametros!$F$19)<=0,1000000000,MAX(Parametros!$B$19,(D5+Parametros!$E$19+Parametros!$B$13)/(1-Parametros!$D$19-Parametros!$B$12-Parametros!$B$6-Parametros!$B$5-Parametros!$F$19))) -> 79 | K5: =IF(Parametros!$B$8=1,CEILING(IF(F5<Parametros!$C$15,F5,IF(G5<Parametros!$C$16,G5,IF(H5<Parametros!$C$17,H5,IF(I5<Parametros!$C$18,I5,J5))))+0.1,1)-0.1,ROUNDUP(IF(F5<Parametros!$C$15,F5,IF(G5<Parametros!$C$16,G5,IF(H5<Parametros!$C$17,H5,IF(I5<Parametros!$C$18,I5,J5)))),2)) -> 16.9 | L5: =K5-K5*(INDEX(Parametros!$D$15:$D$19,MATCH(K5,Parametros!$B$15:$B$19,1))+Parametros!$B$12+Parametros!$B$6+INDEX(Parametros!$F$15:$F$19,MATCH(K5,Parametros!$B$15:$B$19,1)))-INDEX(Parametros!$E$15:$E$19,MATCH(K5,Parametros!$B$15:$B$19,1))-Parametros!$B$13-D5 -> 3.548 | M5: =L5/K5 -> 0.20994083 | N5: =IF((1-Parametros!$D$26-Parametros!$B$23-Parametros!$B$6-Parametros!$B$5-Parametros!$F$26)<=0,1000000000,MAX(Parametros!$B$26,(D5+Parametros!$E$26+Parametros!$B$24)/(1-Parametros!$D$26-Parametros!$B$23-Parametros!$B$6-Parametros!$B$5-Parametros!$F$26))) -> 67.666667 | O5: =IF((1-Parametros!$D$27-Parametros!$B$23-Parametros!$B$6-Parametros!$B$5-Parametros!$F$27)<=0,1000000000,MAX(Parametros!$B$27,(D5+Parametros!$E$27+Parametros!$B$24)/(1-Parametros!$D$27-Parametros!$B$23-Parametros!$B$6-Parametros!$B$5-Parametros!$F$27))) -> 14.392857 | P5: =IF(Parametros!$B$8=1,CEILING(IF(N5<Parametros!$C$26,N5,O5)+0.1,1)-0.1,ROUNDUP(IF(N5<Parametros!$C$26,N5,O5),2)) -> 14.9 | Q5: =P5-P5*(INDEX(Parametros!$D$26:$D$27,MATCH(P5,Parametros!$B$26:$B$27,1))+Parametros!$B$23+Parametros!$B$6+INDEX(Parametros!$F$26:$F$27,MATCH(P5,Parametros!$B$26:$B$27,1)))-INDEX(Parametros!$E$26:$E$27,MATCH(P5,Parametros!$B$26:$B$27,1))-Parametros!$B$24-D5 -> 3.264 | R5: =Q5/P5 -> 0.2190604 | S5: =IF((1-Parametros!$D$33-Parametros!$B$30-Parametros!$B$6-Parametros!$B$5-Parametros!$F$33)<=0,1000000000,MAX(Parametros!$B$33,(D5+Parametros!$E$33+Parametros!$B$31)/(1-Parametros!$D$33-Parametros!$B$30-Parametros!$B$6-Parametros!$B$5-Parametros!$F$33))) -> 12.212121 | T5: =IF((1-Parametros!$D$34-Parametros!$B$30-Parametros!$B$6-Parametros!$B$5-Parametros!$F$34)<=0,1000000000,MAX(Parametros!$B$34,(D5+Parametros!$E$34+Parametros!$B$31)/(1-Parametros!$D$34-Parametros!$B$30-Parametros!$B$6-Parametros!$B$5-Parametros!$F$34))) -> 50 | U5: =IF(Parametros!$B$8=1,CEILING(IF(S5<Parametros!$C$33,S5,T5)+0.1,1)-0.1,ROUNDUP(IF(S5<Parametros!$C$33,S5,T5),2)) -> 12.9 | V5: =U5-U5*(INDEX(Parametros!$D$33:$D$34,MATCH(U5,Parametros!$B$33:$B$34,1))+Parametros!$B$30+Parametros!$B$6+INDEX(Parametros!$F$33:$F$34,MATCH(U5,Parametros!$B$33:$B$34,1)))-INDEX(Parametros!$E$33:$E$34,MATCH(U5,Parametros!$B$33:$B$34,1))-Parametros!$B$31-D5 -> 3.034 | W5: =V5/U5 -> 0.2351938 | X5: =IF(Parametros!$B$8=1,CEILING((D5+Parametros!$B$39)/(1-Parametros!$B$37-Parametros!$B$38-Parametros!$B$6-Parametros!$B$9)+0.1,1)-0.1,ROUNDUP((D5+Parametros!$B$39)/(1-Parametros!$B$37-Parametros!$B$38-Parametros!$B$6-Parametros!$B$9),2)) -> 8.9 | Y5: =X5-X5*(Parametros!$B$37+Parametros!$B$38+Parametros!$B$6)-Parametros!$B$39-D5 -> 4.484 | Z5: =Y5/X5 -> 0.50382022
A6: =Planilha1!A6 -> 3 | B6: =Planilha1!B6 -> Bolinha de Purga | C6: =Planilha1!C6 -> 3.47 | D6: =C6+Parametros!$B$7 -> 4.47 | E6: =IF(Parametros!$B$8=1,CEILING(D6/(1-Parametros!$B$9-Parametros!$B$6)+0.1,1)-0.1,ROUNDUP(D6/(1-Parametros!$B$9-Parametros!$B$6),2)) -> 9.9 | F6: =IF((1-Parametros!$D$15-Parametros!$B$12-Parametros!$B$6-Parametros!$B$5-Parametros!$F$15)<=0,1000000000,MAX(Parametros!$B$15,(D6+Parametros!$E$15+Parametros!$B$13)/(1-Parametros!$D$15-Parametros!$B$12-Parametros!$B$6-Parametros!$B$5-Parametros!$F$15))) -> 37.25 | G6: =IF((1-Parametros!$D$16-Parametros!$B$12-Parametros!$B$6-Parametros!$B$5-Parametros!$F$16)<=0,1000000000,MAX(Parametros!$B$16,(D6+Parametros!$E$16+Parametros!$B$13)/(1-Parametros!$D$16-Parametros!$B$12-Parametros!$B$6-Parametros!$B$5-Parametros!$F$16))) -> 17.290323 | H6: =IF((1-Parametros!$D$17-Parametros!$B$12-Parametros!$B$6-Parametros!$B$5-Parametros!$F$17)<=0,1000000000,MAX(Parametros!$B$17,(D6+Parametros!$E$17+Parametros!$B$13)/(1-Parametros!$D$17-Parametros!$B$12-Parametros!$B$6-Parametros!$B$5-Parametros!$F$17))) -> 29 | I6: =IF((1-Parametros!$D$18-Parametros!$B$12-Parametros!$B$6-Parametros!$B$5-Parametros!$F$18)<=0,1000000000,MAX(Parametros!$B$18,(D6+Parametros!$E$18+Parametros!$B$13)/(1-Parametros!$D$18-Parametros!$B$12-Parametros!$B$6-Parametros!$B$5-Parametros!$F$18))) -> 50 | J6: =IF((1-Parametros!$D$19-Parametros!$B$12-Parametros!$B$6-Parametros!$B$5-Parametros!$F$19)<=0,1000000000,MAX(Parametros!$B$19,(D6+Parametros!$E$19+Parametros!$B$13)/(1-Parametros!$D$19-Parametros!$B$12-Parametros!$B$6-Parametros!$B$5-Parametros!$F$19))) -> 79 | K6: =IF(Parametros!$B$8=1,CEILING(IF(F6<Parametros!$C$15,F6,IF(G6<Parametros!$C$16,G6,IF(H6<Parametros!$C$17,H6,IF(I6<Parametros!$C$18,I6,J6))))+0.1,1)-0.1,ROUNDUP(IF(F6<Parametros!$C$15,F6,IF(G6<Parametros!$C$16,G6,IF(H6<Parametros!$C$17,H6,IF(I6<Parametros!$C$18,I6,J6)))),2)) -> 17.9 | L6: =K6-K6*(INDEX(Parametros!$D$15:$D$19,MATCH(K6,Parametros!$B$15:$B$19,1))+Parametros!$B$12+Parametros!$B$6+INDEX(Parametros!$F$15:$F$19,MATCH(K6,Parametros!$B$15:$B$19,1)))-INDEX(Parametros!$E$15:$E$19,MATCH(K6,Parametros!$B$15:$B$19,1))-Parametros!$B$13-D6 -> 3.958 | M6: =L6/K6 -> 0.22111732 | N6: =IF((1-Parametros!$D$26-Parametros!$B$23-Parametros!$B$6-Parametros!$B$5-Parametros!$F$26)<=0,1000000000,MAX(Parametros!$B$26,(D6+Parametros!$E$26+Parametros!$B$24)/(1-Parametros!$D$26-Parametros!$B$23-Parametros!$B$6-Parametros!$B$5-Parametros!$F$26))) -> 74.5 | O6: =IF((1-Parametros!$D$27-Parametros!$B$23-Parametros!$B$6-Parametros!$B$5-Parametros!$F$27)<=0,1000000000,MAX(Parametros!$B$27,(D6+Parametros!$E$27+Parametros!$B$24)/(1-Parametros!$D$27-Parametros!$B$23-Parametros!$B$6-Parametros!$B$5-Parametros!$F$27))) -> 15.125 | P6: =IF(Parametros!$B$8=1,CEILING(IF(N6<Parametros!$C$26,N6,O6)+0.1,1)-0.1,ROUNDUP(IF(N6<Parametros!$C$26,N6,O6),2)) -> 15.9 | Q6: =P6-P6*(INDEX(Parametros!$D$26:$D$27,MATCH(P6,Parametros!$B$26:$B$27,1))+Parametros!$B$23+Parametros!$B$6+INDEX(Parametros!$F$26:$F$27,MATCH(P6,Parametros!$B$26:$B$27,1)))-INDEX(Parametros!$E$26:$E$27,MATCH(P6,Parametros!$B$26:$B$27,1))-Parametros!$B$24-D6 -> 3.614 | R6: =Q6/P6 -> 0.2272956 | S6: =IF((1-Parametros!$D$33-Parametros!$B$30-Parametros!$B$6-Parametros!$B$5-Parametros!$F$33)<=0,1000000000,MAX(Parametros!$B$33,(D6+Parametros!$E$33+Parametros!$B$31)/(1-Parametros!$D$33-Parametros!$B$30-Parametros!$B$6-Parametros!$B$5-Parametros!$F$33))) -> 12.833333 | T6: =IF((1-Parametros!$D$34-Parametros!$B$30-Parametros!$B$6-Parametros!$B$5-Parametros!$F$34)<=0,1000000000,MAX(Parametros!$B$34,(D6+Parametros!$E$34+Parametros!$B$31)/(1-Parametros!$D$34-Parametros!$B$30-Parametros!$B$6-Parametros!$B$5-Parametros!$F$34))) -> 50 | U6: =IF(Parametros!$B$8=1,CEILING(IF(S6<Parametros!$C$33,S6,T6)+0.1,1)-0.1,ROUNDUP(IF(S6<Parametros!$C$33,S6,T6),2)) -> 12.9 | V6: =U6-U6*(INDEX(Parametros!$D$33:$D$34,MATCH(U6,Parametros!$B$33:$B$34,1))+Parametros!$B$30+Parametros!$B$6+INDEX(Parametros!$F$33:$F$34,MATCH(U6,Parametros!$B$33:$B$34,1)))-INDEX(Parametros!$E$33:$E$34,MATCH(U6,Parametros!$B$33:$B$34,1))-Parametros!$B$31-D6 -> 2.624 | W6: =V6/U6 -> 0.20341085 | X6: =IF(Parametros!$B$8=1,CEILING((D6+Parametros!$B$39)/(1-Parametros!$B$37-Parametros!$B$38-Parametros!$B$6-Parametros!$B$9)+0.1,1)-0.1,ROUNDUP((D6+Parametros!$B$39)/(1-Parametros!$B$37-Parametros!$B$38-Parametros!$B$6-Parametros!$B$9),2)) -> 9.9 | Y6: =X6-X6*(Parametros!$B$37+Parametros!$B$38+Parametros!$B$6)-Parametros!$B$39-D6 -> 5.034 | Z6: =Y6/X6 -> 0.50848485
A7: =Planilha1!A7 -> 4 | B7: =Planilha1!B7 -> Brinquedo Rato médio | C7: =Planilha1!C7 -> 2.49 | D7: =C7+Parametros!$B$7 -> 3.49 | E7: =IF(Parametros!$B$8=1,CEILING(D7/(1-Parametros!$B$9-Parametros!$B$6)+0.1,1)-0.1,ROUNDUP(D7/(1-Parametros!$B$9-Parametros!$B$6),2)) -> 7.9 | F7: =IF((1-Parametros!$D$15-Parametros!$B$12-Parametros!$B$6-Parametros!$B$5-Parametros!$F$15)<=0,1000000000,MAX(Parametros!$B$15,(D7+Parametros!$E$15+Parametros!$B$13)/(1-Parametros!$D$15-Parametros!$B$12-Parametros!$B$6-Parametros!$B$5-Parametros!$F$15))) -> 29.083333 | G7: =IF((1-Parametros!$D$16-Parametros!$B$12-Parametros!$B$6-Parametros!$B$5-Parametros!$F$16)<=0,1000000000,MAX(Parametros!$B$16,(D7+Parametros!$E$16+Parametros!$B$13)/(1-Parametros!$D$16-Parametros!$B$12-Parametros!$B$6-Parametros!$B$5-Parametros!$F$16))) -> 15.709677 | H7: =IF((1-Parametros!$D$17-Parametros!$B$12-Parametros!$B$6-Parametros!$B$5-Parametros!$F$17)<=0,1000000000,MAX(Parametros!$B$17,(D7+Parametros!$E$17+Parametros!$B$13)/(1-Parametros!$D$17-Parametros!$B$12-Parametros!$B$6-Parametros!$B$5-Parametros!$F$17))) -> 29 | I7: =IF((1-Parametros!$D$18-Parametros!$B$12-Parametros!$B$6-Parametros!$B$5-Parametros!$F$18)<=0,1000000000,MAX(Parametros!$B$18,(D7+Parametros!$E$18+Parametros!$B$13)/(1-Parametros!$D$18-Parametros!$B$12-Parametros!$B$6-Parametros!$B$5-Parametros!$F$18))) -> 50 | J7: =IF((1-Parametros!$D$19-Parametros!$B$12-Parametros!$B$6-Parametros!$B$5-Parametros!$F$19)<=0,1000000000,MAX(Parametros!$B$19,(D7+Parametros!$E$19+Parametros!$B$13)/(1-Parametros!$D$19-Parametros!$B$12-Parametros!$B$6-Parametros!$B$5-Parametros!$F$19))) -> 79 | K7: =IF(Parametros!$B$8=1,CEILING(IF(F7<Parametros!$C$15,F7,IF(G7<Parametros!$C$16,G7,IF(H7<Parametros!$C$17,H7,IF(I7<Parametros!$C$18,I7,J7))))+0.1,1)-0.1,ROUNDUP(IF(F7<Parametros!$C$15,F7,IF(G7<Parametros!$C$16,G7,IF(H7<Parametros!$C$17,H7,IF(I7<Parametros!$C$18,I7,J7)))),2)) -> 15.9 | L7: =K7-K7*(INDEX(Parametros!$D$15:$D$19,MATCH(K7,Parametros!$B$15:$B$19,1))+Parametros!$B$12+Parametros!$B$6+INDEX(Parametros!$F$15:$F$19,MATCH(K7,Parametros!$B$15:$B$19,1)))-INDEX(Parametros!$E$15:$E$19,MATCH(K7,Parametros!$B$15:$B$19,1))-Parametros!$B$13-D7 -> 3.298 | M7: =L7/K7 -> 0.20742138 | N7: =IF((1-Parametros!$D$26-Parametros!$B$23-Parametros!$B$6-Parametros!$B$5-Parametros!$F$26)<=0,1000000000,MAX(Parametros!$B$26,(D7+Parametros!$E$26+Parametros!$B$24)/(1-Parametros!$D$26-Parametros!$B$23-Parametros!$B$6-Parametros!$B$5-Parametros!$F$26))) -> 58.166667 | O7: =IF((1-Parametros!$D$27-Parametros!$B$23-Parametros!$B$6-Parametros!$B$5-Parametros!$F$27)<=0,1000000000,MAX(Parametros!$B$27,(D7+Parametros!$E$27+Parametros!$B$24)/(1-Parametros!$D$27-Parametros!$B$23-Parametros!$B$6-Parametros!$B$5-Parametros!$F$27))) -> 13.375 | P7: =IF(Parametros!$B$8=1,CEILING(IF(N7<Parametros!$C$26,N7,O7)+0.1,1)-0.1,ROUNDUP(IF(N7<Parametros!$C$26,N7,O7),2)) -> 13.9 | Q7: =P7-P7*(INDEX(Parametros!$D$26:$D$27,MATCH(P7,Parametros!$B$26:$B$27,1))+Parametros!$B$23+Parametros!$B$6+INDEX(Parametros!$F$26:$F$27,MATCH(P7,Parametros!$B$26:$B$27,1)))-INDEX(Parametros!$E$26:$E$27,MATCH(P7,Parametros!$B$26:$B$27,1))-Parametros!$B$24-D7 -> 3.074 | R7: =Q7/P7 -> 0.22115108 | S7: =IF((1-Parametros!$D$33-Parametros!$B$30-Parametros!$B$6-Parametros!$B$5-Parametros!$F$33)<=0,1000000000,MAX(Parametros!$B$33,(D7+Parametros!$E$33+Parametros!$B$31)/(1-Parametros!$D$33-Parametros!$B$30-Parametros!$B$6-Parametros!$B$5-Parametros!$F$33))) -> 11.348485 | T7: =IF((1-Parametros!$D$34-Parametros!$B$30-Parametros!$B$6-Parametros!$B$5-Parametros!$F$34)<=0,1000000000,MAX(Parametros!$B$34,(D7+Parametros!$E$34+Parametros!$B$31)/(1-Parametros!$D$34-Parametros!$B$30-Parametros!$B$6-Parametros!$B$5-Parametros!$F$34))) -> 50 | U7: =IF(Parametros!$B$8=1,CEILING(IF(S7<Parametros!$C$33,S7,T7)+0.1,1)-0.1,ROUNDUP(IF(S7<Parametros!$C$33,S7,T7),2)) -> 11.9 | V7: =U7-U7*(INDEX(Parametros!$D$33:$D$34,MATCH(U7,Parametros!$B$33:$B$34,1))+Parametros!$B$30+Parametros!$B$6+INDEX(Parametros!$F$33:$F$34,MATCH(U7,Parametros!$B$33:$B$34,1)))-INDEX(Parametros!$E$33:$E$34,MATCH(U7,Parametros!$B$33:$B$34,1))-Parametros!$B$31-D7 -> 2.744 | W7: =V7/U7 -> 0.23058824 | X7: =IF(Parametros!$B$8=1,CEILING((D7+Parametros!$B$39)/(1-Parametros!$B$37-Parametros!$B$38-Parametros!$B$6-Parametros!$B$9)+0.1,1)-0.1,ROUNDUP((D7+Parametros!$B$39)/(1-Parametros!$B$37-Parametros!$B$38-Parametros!$B$6-Parametros!$B$9),2)) -> 7.9 | Y7: =X7-X7*(Parametros!$B$37+Parametros!$B$38+Parametros!$B$6)-Parametros!$B$39-D7 -> 4.094 | Z7: =Y7/X7 -> 0.51822785
A8: =Planilha1!A8 -> 5 | B8: =Planilha1!B8 -> Brinquedo Rato articulado | C8: =Planilha1!C8 -> 2.81 | D8: =C8+Parametros!$B$7 -> 3.81 | E8: =IF(Parametros!$B$8=1,CEILING(D8/(1-Parametros!$B$9-Parametros!$B$6)+0.1,1)-0.1,ROUNDUP(D8/(1-Parametros!$B$9-Parametros!$B$6),2)) -> 8.9 | F8: =IF((1-Parametros!$D$15-Parametros!$B$12-Parametros!$B$6-Parametros!$B$5-Parametros!$F$15)<=0,1000000000,MAX(Parametros!$B$15,(D8+Parametros!$E$15+Parametros!$B$13)/(1-Parametros!$D$15-Parametros!$B$12-Parametros!$B$6-Parametros!$B$5-Parametros!$F$15))) -> 31.75 | G8: =IF((1-Parametros!$D$16-Parametros!$B$12-Parametros!$B$6-Parametros!$B$5-Parametros!$F$16)<=0,1000000000,MAX(Parametros!$B$16,(D8+Parametros!$E$16+Parametros!$B$13)/(1-Parametros!$D$16-Parametros!$B$12-Parametros!$B$6-Parametros!$B$5-Parametros!$F$16))) -> 16.225806 | H8: =IF((1-Parametros!$D$17-Parametros!$B$12-Parametros!$B$6-Parametros!$B$5-Parametros!$F$17)<=0,1000000000,MAX(Parametros!$B$17,(D8+Parametros!$E$17+Parametros!$B$13)/(1-Parametros!$D$17-Parametros!$B$12-Parametros!$B$6-Parametros!$B$5-Parametros!$F$17))) -> 29 | I8: =IF((1-Parametros!$D$18-Parametros!$B$12-Parametros!$B$6-Parametros!$B$5-Parametros!$F$18)<=0,1000000000,MAX(Parametros!$B$18,(D8+Parametros!$E$18+Parametros!$B$13)/(1-Parametros!$D$18-Parametros!$B$12-Parametros!$B$6-Parametros!$B$5-Parametros!$F$18))) -> 50 | J8: =IF((1-Parametros!$D$19-Parametros!$B$12-Parametros!$B$6-Parametros!$B$5-Parametros!$F$19)<=0,1000000000,MAX(Parametros!$B$19,(D8+Parametros!$E$19+Parametros!$B$13)/(1-Parametros!$D$19-Parametros!$B$12-Parametros!$B$6-Parametros!$B$5-Parametros!$F$19))) -> 79 | K8: =IF(Parametros!$B$8=1,CEILING(IF(F8<Parametros!$C$15,F8,IF(G8<Parametros!$C$16,G8,IF(H8<Parametros!$C$17,H8,IF(I8<Parametros!$C$18,I8,J8))))+0.1,1)-0.1,ROUNDUP(IF(F8<Parametros!$C$15,F8,IF(G8<Parametros!$C$16,G8,IF(H8<Parametros!$C$17,H8,IF(I8<Parametros!$C$18,I8,J8)))),2)) -> 16.9 | L8: =K8-K8*(INDEX(Parametros!$D$15:$D$19,MATCH(K8,Parametros!$B$15:$B$19,1))+Parametros!$B$12+Parametros!$B$6+INDEX(Parametros!$F$15:$F$19,MATCH(K8,Parametros!$B$15:$B$19,1)))-INDEX(Parametros!$E$15:$E$19,MATCH(K8,Parametros!$B$15:$B$19,1))-Parametros!$B$13-D8 -> 3.798 | M8: =L8/K8 -> 0.22473373 | N8: =IF((1-Parametros!$D$26-Parametros!$B$23-Parametros!$B$6-Parametros!$B$5-Parametros!$F$26)<=0,1000000000,MAX(Parametros!$B$26,(D8+Parametros!$E$26+Parametros!$B$24)/(1-Parametros!$D$26-Parametros!$B$23-Parametros!$B$6-Parametros!$B$5-Parametros!$F$26))) -> 63.5 | O8: =IF((1-Parametros!$D$27-Parametros!$B$23-Parametros!$B$6-Parametros!$B$5-Parametros!$F$27)<=0,1000000000,MAX(Parametros!$B$27,(D8+Parametros!$E$27+Parametros!$B$24)/(1-Parametros!$D$27-Parametros!$B$23-Parametros!$B$6-Parametros!$B$5-Parametros!$F$27))) -> 13.946429 | P8: =IF(Parametros!$B$8=1,CEILING(IF(N8<Parametros!$C$26,N8,O8)+0.1,1)-0.1,ROUNDUP(IF(N8<Parametros!$C$26,N8,O8),2)) -> 14.9 | Q8: =P8-P8*(INDEX(Parametros!$D$26:$D$27,MATCH(P8,Parametros!$B$26:$B$27,1))+Parametros!$B$23+Parametros!$B$6+INDEX(Parametros!$F$26:$F$27,MATCH(P8,Parametros!$B$26:$B$27,1)))-INDEX(Parametros!$E$26:$E$27,MATCH(P8,Parametros!$B$26:$B$27,1))-Parametros!$B$24-D8 -> 3.514 | R8: =Q8/P8 -> 0.23583893 | S8: =IF((1-Parametros!$D$33-Parametros!$B$30-Parametros!$B$6-Parametros!$B$5-Parametros!$F$33)<=0,1000000000,MAX(Parametros!$B$33,(D8+Parametros!$E$33+Parametros!$B$31)/(1-Parametros!$D$33-Parametros!$B$30-Parametros!$B$6-Parametros!$B$5-Parametros!$F$33))) -> 11.833333 | T8: =IF((1-Parametros!$D$34-Parametros!$B$30-Parametros!$B$6-Parametros!$B$5-Parametros!$F$34)<=0,1000000000,MAX(Parametros!$B$34,(D8+Parametros!$E$34+Parametros!$B$31)/(1-Parametros!$D$34-Parametros!$B$30-Parametros!$B$6-Parametros!$B$5-Parametros!$F$34))) -> 50 | U8: =IF(Parametros!$B$8=1,CEILING(IF(S8<Parametros!$C$33,S8,T8)+0.1,1)-0.1,ROUNDUP(IF(S8<Parametros!$C$33,S8,T8),2)) -> 11.9 | V8: =U8-U8*(INDEX(Parametros!$D$33:$D$34,MATCH(U8,Parametros!$B$33:$B$34,1))+Parametros!$B$30+Parametros!$B$6+INDEX(Parametros!$F$33:$F$34,MATCH(U8,Parametros!$B$33:$B$34,1)))-INDEX(Parametros!$E$33:$E$34,MATCH(U8,Parametros!$B$33:$B$34,1))-Parametros!$B$31-D8 -> 2.424 | W8: =V8/U8 -> 0.20369748 | X8: =IF(Parametros!$B$8=1,CEILING((D8+Parametros!$B$39)/(1-Parametros!$B$37-Parametros!$B$38-Parametros!$B$6-Parametros!$B$9)+0.1,1)-0.1,ROUNDUP((D8+Parametros!$B$39)/(1-Parametros!$B$37-Parametros!$B$38-Parametros!$B$6-Parametros!$B$9),2)) -> 8.9 | Y8: =X8-X8*(Parametros!$B$37+Parametros!$B$38+Parametros!$B$6)-Parametros!$B$39-D8 -> 4.734 | Z8: =Y8/X8 -> 0.53191011
A9: =Planilha1!A9 -> 6 | B9: =Planilha1!B9 -> Chaveiro Clic vaso Gato | C9: =Planilha1!C9 -> 4.73 | D9: =C9+Parametros!$B$7 -> 5.73 | E9: =IF(Parametros!$B$8=1,CEILING(D9/(1-Parametros!$B$9-Parametros!$B$6)+0.1,1)-0.1,ROUNDUP(D9/(1-Parametros!$B$9-Parametros!$B$6),2)) -> 12.9 | F9: =IF((1-Parametros!$D$15-Parametros!$B$12-Parametros!$B$6-Parametros!$B$5-Parametros!$F$15)<=0,1000000000,MAX(Parametros!$B$15,(D9+Parametros!$E$15+Parametros!$B$13)/(1-Parametros!$D$15-Parametros!$B$12-Parametros!$B$6-Parametros!$B$5-Parametros!$F$15))) -> 47.75 | G9: =IF((1-Parametros!$D$16-Parametros!$B$12-Parametros!$B$6-Parametros!$B$5-Parametros!$F$16)<=0,1000000000,MAX(Parametros!$B$16,(D9+Parametros!$E$16+Parametros!$B$13)/(1-Parametros!$D$16-Parametros!$B$12-Parametros!$B$6-Parametros!$B$5-Parametros!$F$16))) -> 19.322581 | H9: =IF((1-Parametros!$D$17-Parametros!$B$12-Parametros!$B$6-Parametros!$B$5-Parametros!$F$17)<=0,1000000000,MAX(Parametros!$B$17,(D9+Parametros!$E$17+Parametros!$B$13)/(1-Parametros!$D$17-Parametros!$B$12-Parametros!$B$6-Parametros!$B$5-Parametros!$F$17))) -> 29 | I9: =IF((1-Parametros!$D$18-Parametros!$B$12-Parametros!$B$6-Parametros!$B$5-Parametros!$F$18)<=0,1000000000,MAX(Parametros!$B$18,(D9+Parametros!$E$18+Parametros!$B$13)/(1-Parametros!$D$18-Parametros!$B$12-Parametros!$B$6-Parametros!$B$5-Parametros!$F$18))) -> 50 | J9: =IF((1-Parametros!$D$19-Parametros!$B$12-Parametros!$B$6-Parametros!$B$5-Parametros!$F$19)<=0,1000000000,MAX(Parametros!$B$19,(D9+Parametros!$E$19+Parametros!$B$13)/(1-Parametros!$D$19-Parametros!$B$12-Parametros!$B$6-Parametros!$B$5-Parametros!$F$19))) -> 79 | K9: =IF(Parametros!$B$8=1,CEILING(IF(F9<Parametros!$C$15,F9,IF(G9<Parametros!$C$16,G9,IF(H9<Parametros!$C$17,H9,IF(I9<Parametros!$C$18,I9,J9))))+0.1,1)-0.1,ROUNDUP(IF(F9<Parametros!$C$15,F9,IF(G9<Parametros!$C$16,G9,IF(H9<Parametros!$C$17,H9,IF(I9<Parametros!$C$18,I9,J9)))),2)) -> 19.9 | L9: =K9-K9*(INDEX(Parametros!$D$15:$D$19,MATCH(K9,Parametros!$B$15:$B$19,1))+Parametros!$B$12+Parametros!$B$6+INDEX(Parametros!$F$15:$F$19,MATCH(K9,Parametros!$B$15:$B$19,1)))-INDEX(Parametros!$E$15:$E$19,MATCH(K9,Parametros!$B$15:$B$19,1))-Parametros!$B$13-D9 -> 4.338 | M9: =L9/K9 -> 0.21798995 | N9: =IF((1-Parametros!$D$26-Parametros!$B$23-Parametros!$B$6-Parametros!$B$5-Parametros!$F$26)<=0,1000000000,MAX(Parametros!$B$26,(D9+Parametros!$E$26+Parametros!$B$24)/(1-Parametros!$D$26-Parametros!$B$23-Parametros!$B$6-Parametros!$B$5-Parametros!$F$26))) -> 95.5 | O9: =IF((1-Parametros!$D$27-Parametros!$B$23-Parametros!$B$6-Parametros!$B$5-Parametros!$F$27)<=0,1000000000,MAX(Parametros!$B$27,(D9+Parametros!$E$27+Parametros!$B$24)/(1-Parametros!$D$27-Parametros!$B$23-Parametros!$B$6-Parametros!$B$5-Parametros!$F$27))) -> 17.375 | P9: =IF(Parametros!$B$8=1,CEILING(IF(N9<Parametros!$C$26,N9,O9)+0.1,1)-0.1,ROUNDUP(IF(N9<Parametros!$C$26,N9,O9),2)) -> 17.9 | Q9: =P9-P9*(INDEX(Parametros!$D$26:$D$27,MATCH(P9,Parametros!$B$26:$B$27,1))+Parametros!$B$23+Parametros!$B$6+INDEX(Parametros!$F$26:$F$27,MATCH(P9,Parametros!$B$26:$B$27,1)))-INDEX(Parametros!$E$26:$E$27,MATCH(P9,Parametros!$B$26:$B$27,1))-Parametros!$B$24-D9 -> 3.874 | R9: =Q9/P9 -> 0.21642458 | S9: =IF((1-Parametros!$D$33-Parametros!$B$30-Parametros!$B$6-Parametros!$B$5-Parametros!$F$33)<=0,1000000000,MAX(Parametros!$B$33,(D9+Parametros!$E$33+Parametros!$B$31)/(1-Parametros!$D$33-Parametros!$B$30-Parametros!$B$6-Parametros!$B$5-Parametros!$F$33))) -> 14.742424 | T9: =IF((1-Parametros!$D$34-Parametros!$B$30-Parametros!$B$6-Parametros!$B$5-Parametros!$F$34)<=0,1000000000,MAX(Parametros!$B$34,(D9+Parametros!$E$34+Parametros!$B$31)/(1-Parametros!$D$34-Parametros!$B$30-Parametros!$B$6-Parametros!$B$5-Parametros!$F$34))) -> 50 | U9: =IF(Parametros!$B$8=1,CEILING(IF(S9<Parametros!$C$33,S9,T9)+0.1,1)-0.1,ROUNDUP(IF(S9<Parametros!$C$33,S9,T9),2)) -> 14.9 | V9: =U9-U9*(INDEX(Parametros!$D$33:$D$34,MATCH(U9,Parametros!$B$33:$B$34,1))+Parametros!$B$30+Parametros!$B$6+INDEX(Parametros!$F$33:$F$34,MATCH(U9,Parametros!$B$33:$B$34,1)))-INDEX(Parametros!$E$33:$E$34,MATCH(U9,Parametros!$B$33:$B$34,1))-Parametros!$B$31-D9 -> 3.084 | W9: =V9/U9 -> 0.20697987 | X9: =IF(Parametros!$B$8=1,CEILING((D9+Parametros!$B$39)/(1-Parametros!$B$37-Parametros!$B$38-Parametros!$B$6-Parametros!$B$9)+0.1,1)-0.1,ROUNDUP((D9+Parametros!$B$39)/(1-Parametros!$B$37-Parametros!$B$38-Parametros!$B$6-Parametros!$B$9),2)) -> 12.9 | Y9: =X9-X9*(Parametros!$B$37+Parametros!$B$38+Parametros!$B$6)-Parametros!$B$39-D9 -> 6.654 | Z9: =Y9/X9 -> 0.51581395
A10: =Planilha1!A10 -> 7 | B10: =Planilha1!B10 -> Chaveiro 4 em 1 (NFC, lata, suporte, chaveiro) | C10: =Planilha1!C10 -> 5.6 | D10: =C10+Parametros!$B$7 -> 6.6 | E10: =IF(Parametros!$B$8=1,CEILING(D10/(1-Parametros!$B$9-Parametros!$B$6)+0.1,1)-0.1,ROUNDUP(D10/(1-Parametros!$B$9-Parametros!$B$6),2)) -> 14.9 | F10: =IF((1-Parametros!$D$15-Parametros!$B$12-Parametros!$B$6-Parametros!$B$5-Parametros!$F$15)<=0,1000000000,MAX(Parametros!$B$15,(D10+Parametros!$E$15+Parametros!$B$13)/(1-Parametros!$D$15-Parametros!$B$12-Parametros!$B$6-Parametros!$B$5-Parametros!$F$15))) -> 55 | G10: =IF((1-Parametros!$D$16-Parametros!$B$12-Parametros!$B$6-Parametros!$B$5-Parametros!$F$16)<=0,1000000000,MAX(Parametros!$B$16,(D10+Parametros!$E$16+Parametros!$B$13)/(1-Parametros!$D$16-Parametros!$B$12-Parametros!$B$6-Parametros!$B$5-Parametros!$F$16))) -> 20.725806 | H10: =IF((1-Parametros!$D$17-Parametros!$B$12-Parametros!$B$6-Parametros!$B$5-Parametros!$F$17)<=0,1000000000,MAX(Parametros!$B$17,(D10+Parametros!$E$17+Parametros!$B$13)/(1-Parametros!$D$17-Parametros!$B$12-Parametros!$B$6-Parametros!$B$5-Parametros!$F$17))) -> 29 | I10: =IF((1-Parametros!$D$18-Parametros!$B$12-Parametros!$B$6-Parametros!$B$5-Parametros!$F$18)<=0,1000000000,MAX(Parametros!$B$18,(D10+Parametros!$E$18+Parametros!$B$13)/(1-Parametros!$D$18-Parametros!$B$12-Parametros!$B$6-Parametros!$B$5-Parametros!$F$18))) -> 50 | J10: =IF((1-Parametros!$D$19-Parametros!$B$12-Parametros!$B$6-Parametros!$B$5-Parametros!$F$19)<=0,1000000000,MAX(Parametros!$B$19,(D10+Parametros!$E$19+Parametros!$B$13)/(1-Parametros!$D$19-Parametros!$B$12-Parametros!$B$6-Parametros!$B$5-Parametros!$F$19))) -> 79 | K10: =IF(Parametros!$B$8=1,CEILING(IF(F10<Parametros!$C$15,F10,IF(G10<Parametros!$C$16,G10,IF(H10<Parametros!$C$17,H10,IF(I10<Parametros!$C$18,I10,J10))))+0.1,1)-0.1,ROUNDUP(IF(F10<Parametros!$C$15,F10,IF(G10<Parametros!$C$16,G10,IF(H10<Parametros!$C$17,H10,IF(I10<Parametros!$C$18,I10,J10)))),2)) -> 20.9 | L10: =K10-K10*(INDEX(Parametros!$D$15:$D$19,MATCH(K10,Parametros!$B$15:$B$19,1))+Parametros!$B$12+Parametros!$B$6+INDEX(Parametros!$F$15:$F$19,MATCH(K10,Parametros!$B$15:$B$19,1)))-INDEX(Parametros!$E$15:$E$19,MATCH(K10,Parametros!$B$15:$B$19,1))-Parametros!$B$13-D10 -> 4.288 | M10: =L10/K10 -> 0.20516746 | N10: =IF((1-Parametros!$D$26-Parametros!$B$23-Parametros!$B$6-Parametros!$B$5-Parametros!$F$26)<=0,1000000000,MAX(Parametros!$B$26,(D10+Parametros!$E$26+Parametros!$B$24)/(1-Parametros!$D$26-Parametros!$B$23-Parametros!$B$6-Parametros!$B$5-Parametros!$F$26))) -> 110 | O10: =IF((1-Parametros!$D$27-Parametros!$B$23-Parametros!$B$6-Parametros!$B$5-Parametros!$F$27)<=0,1000000000,MAX(Parametros!$B$27,(D10+Parametros!$E$27+Parametros!$B$24)/(1-Parametros!$D$27-Parametros!$B$23-Parametros!$B$6-Parametros!$B$5-Parametros!$F$27))) -> 18.928571 | P10: =IF(Parametros!$B$8=1,CEILING(IF(N10<Parametros!$C$26,N10,O10)+0.1,1)-0.1,ROUNDUP(IF(N10<Parametros!$C$26,N10,O10),2)) -> 19.9 | Q10: =P10-P10*(INDEX(Parametros!$D$26:$D$27,MATCH(P10,Parametros!$B$26:$B$27,1))+Parametros!$B$23+Parametros!$B$6+INDEX(Parametros!$F$26:$F$27,MATCH(P10,Parametros!$B$26:$B$27,1)))-INDEX(Parametros!$E$26:$E$27,MATCH(P10,Parametros!$B$26:$B$27,1))-Parametros!$B$24-D10 -> 4.524 | R10: =Q10/P10 -> 0.22733668 | S10: =IF((1-Parametros!$D$33-Parametros!$B$30-Parametros!$B$6-Parametros!$B$5-Parametros!$F$33)<=0,1000000000,MAX(Parametros!$B$33,(D10+Parametros!$E$33+Parametros!$B$31)/(1-Parametros!$D$33-Parametros!$B$30-Parametros!$B$6-Parametros!$B$5-Parametros!$F$33))) -> 16.060606 | T10: =IF((1-Parametros!$D$34-Parametros!$B$30-Parametros!$B$6-Parametros!$B$5-Parametros!$F$34)<=0,1000000000,MAX(Parametros!$B$34,(D10+Parametros!$E$34+Parametros!$B$31)/(1-Parametros!$D$34-Parametros!$B$30-Parametros!$B$6-Parametros!$B$5-Parametros!$F$34))) -> 50 | U10: =IF(Parametros!$B$8=1,CEILING(IF(S10<Parametros!$C$33,S10,T10)+0.1,1)-0.1,ROUNDUP(IF(S10<Parametros!$C$33,S10,T10),2)) -> 16.9 | V10: =U10-U10*(INDEX(Parametros!$D$33:$D$34,MATCH(U10,Parametros!$B$33:$B$34,1))+Parametros!$B$30+Parametros!$B$6+INDEX(Parametros!$F$33:$F$34,MATCH(U10,Parametros!$B$33:$B$34,1)))-INDEX(Parametros!$E$33:$E$34,MATCH(U10,Parametros!$B$33:$B$34,1))-Parametros!$B$31-D10 -> 3.934 | W10: =V10/U10 -> 0.23278107 | X10: =IF(Parametros!$B$8=1,CEILING((D10+Parametros!$B$39)/(1-Parametros!$B$37-Parametros!$B$38-Parametros!$B$6-Parametros!$B$9)+0.1,1)-0.1,ROUNDUP((D10+Parametros!$B$39)/(1-Parametros!$B$37-Parametros!$B$38-Parametros!$B$6-Parametros!$B$9),2)) -> 14.9 | Y10: =X10-X10*(Parametros!$B$37+Parametros!$B$38+Parametros!$B$6)-Parametros!$B$39-D10 -> 7.704 | Z10: =Y10/X10 -> 0.51704698
A11: =Planilha1!A11 -> 8 | B11: =Planilha1!B11 -> Chaveiro abre lata pet | C11: =Planilha1!C11 -> 2.76 | D11: =C11+Parametros!$B$7 -> 3.76 | E11: =IF(Parametros!$B$8=1,CEILING(D11/(1-Parametros!$B$9-Parametros!$B$6)+0.1,1)-0.1,ROUNDUP(D11/(1-Parametros!$B$9-Parametros!$B$6),2)) -> 8.9 | F11: =IF((1-Parametros!$D$15-Parametros!$B$12-Parametros!$B$6-Parametros!$B$5-Parametros!$F$15)<=0,1000000000,MAX(Parametros!$B$15,(D11+Parametros!$E$15+Parametros!$B$13)/(1-Parametros!$D$15-Parametros!$B$12-Parametros!$B$6-Parametros!$B$5-Parametros!$F$15))) -> 31.333333 | G11: =IF((1-Parametros!$D$16-Parametros!$B$12-Parametros!$B$6-Parametros!$B$5-Parametros!$F$16)<=0,1000000000,MAX(Parametros!$B$16,(D11+Parametros!$E$16+Parametros!$B$13)/(1-Parametros!$D$16-Parametros!$B$12-Parametros!$B$6-Parametros!$B$5-Parametros!$F$16))) -> 16.145161 | H11: =IF((1-Parametros!$D$17-Parametros!$B$12-Parametros!$B$6-Parametros!$B$5-Parametros!$F$17)<=0,1000000000,MAX(Parametros!$B$17,(D11+Parametros!$E$17+Parametros!$B$13)/(1-Parametros!$D$17-Parametros!$B$12-Parametros!$B$6-Parametros!$B$5-Parametros!$F$17))) -> 29 | I11: =IF((1-Parametros!$D$18-Parametros!$B$12-Parametros!$B$6-Parametros!$B$5-Parametros!$F$18)<=0,1000000000,MAX(Parametros!$B$18,(D11+Parametros!$E$18+Parametros!$B$13)/(1-Parametros!$D$18-Parametros!$B$12-Parametros!$B$6-Parametros!$B$5-Parametros!$F$18))) -> 50 | J11: =IF((1-Parametros!$D$19-Parametros!$B$12-Parametros!$B$6-Parametros!$B$5-Parametros!$F$19)<=0,1000000000,MAX(Parametros!$B$19,(D11+Parametros!$E$19+Parametros!$B$13)/(1-Parametros!$D$19-Parametros!$B$12-Parametros!$B$6-Parametros!$B$5-Parametros!$F$19))) -> 79 | K11: =IF(Parametros!$B$8=1,CEILING(IF(F11<Parametros!$C$15,F11,IF(G11<Parametros!$C$16,G11,IF(H11<Parametros!$C$17,H11,IF(I11<Parametros!$C$18,I11,J11))))+0.1,1)-0.1,ROUNDUP(IF(F11<Parametros!$C$15,F11,IF(G11<Parametros!$C$16,G11,IF(H11<Parametros!$C$17,H11,IF(I11<Parametros!$C$18,I11,J11)))),2)) -> 16.9 | L11: =K11-K11*(INDEX(Parametros!$D$15:$D$19,MATCH(K11,Parametros!$B$15:$B$19,1))+Parametros!$B$12+Parametros!$B$6+INDEX(Parametros!$F$15:$F$19,MATCH(K11,Parametros!$B$15:$B$19,1)))-INDEX(Parametros!$E$15:$E$19,MATCH(K11,Parametros!$B$15:$B$19,1))-Parametros!$B$13-D11 -> 3.848 | M11: =L11/K11 -> 0.22769231 | N11: =IF((1-Parametros!$D$26-Parametros!$B$23-Parametros!$B$6-Parametros!$B$5-Parametros!$F$26)<=0,1000000000,MAX(Parametros!$B$26,(D11+Parametros!$E$26+Parametros!$B$24)/(1-Parametros!$D$26-Parametros!$B$23-Parametros!$B$6-Parametros!$B$5-Parametros!$F$26))) -> 62.666667 | O11: =IF((1-Parametros!$D$27-Parametros!$B$23-Parametros!$B$6-Parametros!$B$5-Parametros!$F$27)<=0,1000000000,MAX(Parametros!$B$27,(D11+Parametros!$E$27+Parametros!$B$24)/(1-Parametros!$D$27-Parametros!$B$23-Parametros!$B$6-Parametros!$B$5-Parametros!$F$27))) -> 13.857143 | P11: =IF(Parametros!$B$8=1,CEILING(IF(N11<Parametros!$C$26,N11,O11)+0.1,1)-0.1,ROUNDUP(IF(N11<Parametros!$C$26,N11,O11),2)) -> 13.9 | Q11: =P11-P11*(INDEX(Parametros!$D$26:$D$27,MATCH(P11,Parametros!$B$26:$B$27,1))+Parametros!$B$23+Parametros!$B$6+INDEX(Parametros!$F$26:$F$27,MATCH(P11,Parametros!$B$26:$B$27,1)))-INDEX(Parametros!$E$26:$E$27,MATCH(P11,Parametros!$B$26:$B$27,1))-Parametros!$B$24-D11 -> 2.804 | R11: =Q11/P11 -> 0.20172662 | S11: =IF((1-Parametros!$D$33-Parametros!$B$30-Parametros!$B$6-Parametros!$B$5-Parametros!$F$33)<=0,1000000000,MAX(Parametros!$B$33,(D11+Parametros!$E$33+Parametros!$B$31)/(1-Parametros!$D$33-Parametros!$B$30-Parametros!$B$6-Parametros!$B$5-Parametros!$F$33))) -> 11.757576 | T11: =IF((1-Parametros!$D$34-Parametros!$B$30-Parametros!$B$6-Parametros!$B$5-Parametros!$F$34)<=0,1000000000,MAX(Parametros!$B$34,(D11+Parametros!$E$34+Parametros!$B$31)/(1-Parametros!$D$34-Parametros!$B$30-Parametros!$B$6-Parametros!$B$5-Parametros!$F$34))) -> 50 | U11: =IF(Parametros!$B$8=1,CEILING(IF(S11<Parametros!$C$33,S11,T11)+0.1,1)-0.1,ROUNDUP(IF(S11<Parametros!$C$33,S11,T11),2)) -> 11.9 | V11: =U11-U11*(INDEX(Parametros!$D$33:$D$34,MATCH(U11,Parametros!$B$33:$B$34,1))+Parametros!$B$30+Parametros!$B$6+INDEX(Parametros!$F$33:$F$34,MATCH(U11,Parametros!$B$33:$B$34,1)))-INDEX(Parametros!$E$33:$E$34,MATCH(U11,Parametros!$B$33:$B$34,1))-Parametros!$B$31-D11 -> 2.474 | W11: =V11/U11 -> 0.20789916 | X11: =IF(Parametros!$B$8=1,CEILING((D11+Parametros!$B$39)/(1-Parametros!$B$37-Parametros!$B$38-Parametros!$B$6-Parametros!$B$9)+0.1,1)-0.1,ROUNDUP((D11+Parametros!$B$39)/(1-Parametros!$B$37-Parametros!$B$38-Parametros!$B$6-Parametros!$B$9),2)) -> 8.9 | Y11: =X11-X11*(Parametros!$B$37+Parametros!$B$38+Parametros!$B$6)-Parametros!$B$39-D11 -> 4.784 | Z11: =Y11/X11 -> 0.53752809
A12: =Planilha1!A12 -> 9 | B12: =Planilha1!B12 -> Chaveiro Gato Soco Ingles | C12: =Planilha1!C12 -> 3.12 | D12: =C12+Parametros!$B$7 -> 4.12 | E12: =IF(Parametros!$B$8=1,CEILING(D12/(1-Parametros!$B$9-Parametros!$B$6)+0.1,1)-0.1,ROUNDUP(D12/(1-Parametros!$B$9-Parametros!$B$6),2)) -> 9.9 | F12: =IF((1-Parametros!$D$15-Parametros!$B$12-Parametros!$B$6-Parametros!$B$5-Parametros!$F$15)<=0,1000000000,MAX(Parametros!$B$15,(D12+Parametros!$E$15+Parametros!$B$13)/(1-Parametros!$D$15-Parametros!$B$12-Parametros!$B$6-Parametros!$B$5-Parametros!$F$15))) -> 34.333333 | G12: =IF((1-Parametros!$D$16-Parametros!$B$12-Parametros!$B$6-Parametros!$B$5-Parametros!$F$16)<=0,1000000000,MAX(Parametros!$B$16,(D12+Parametros!$E$16+Parametros!$B$13)/(1-Parametros!$D$16-Parametros!$B$12-Parametros!$B$6-Parametros!$B$5-Parametros!$F$16))) -> 16.725806 | H12: =IF((1-Parametros!$D$17-Parametros!$B$12-Parametros!$B$6-Parametros!$B$5-Parametros!$F$17)<=0,1000000000,MAX(Parametros!$B$17,(D12+Parametros!$E$17+Parametros!$B$13)/(1-Parametros!$D$17-Parametros!$B$12-Parametros!$B$6-Parametros!$B$5-Parametros!$F$17))) -> 29 | I12: =IF((1-Parametros!$D$18-Parametros!$B$12-Parametros!$B$6-Parametros!$B$5-Parametros!$F$18)<=0,1000000000,MAX(Parametros!$B$18,(D12+Parametros!$E$18+Parametros!$B$13)/(1-Parametros!$D$18-Parametros!$B$12-Parametros!$B$6-Parametros!$B$5-Parametros!$F$18))) -> 50 | J12: =IF((1-Parametros!$D$19-Parametros!$B$12-Parametros!$B$6-Parametros!$B$5-Parametros!$F$19)<=0,1000000000,MAX(Parametros!$B$19,(D12+Parametros!$E$19+Parametros!$B$13)/(1-Parametros!$D$19-Parametros!$B$12-Parametros!$B$6-Parametros!$B$5-Parametros!$F$19))) -> 79 | K12: =IF(Parametros!$B$8=1,CEILING(IF(F12<Parametros!$C$15,F12,IF(G12<Parametros!$C$16,G12,IF(H12<Parametros!$C$17,H12,IF(I12<Parametros!$C$18,I12,J12))))+0.1,1)-0.1,ROUNDUP(IF(F12<Parametros!$C$15,F12,IF(G12<Parametros!$C$16,G12,IF(H12<Parametros!$C$17,H12,IF(I12<Parametros!$C$18,I12,J12)))),2)) -> 16.9 | L12: =K12-K12*(INDEX(Parametros!$D$15:$D$19,MATCH(K12,Parametros!$B$15:$B$19,1))+Parametros!$B$12+Parametros!$B$6+INDEX(Parametros!$F$15:$F$19,MATCH(K12,Parametros!$B$15:$B$19,1)))-INDEX(Parametros!$E$15:$E$19,MATCH(K12,Parametros!$B$15:$B$19,1))-Parametros!$B$13-D12 -> 3.488 | M12: =L12/K12 -> 0.20639053 | N12: =IF((1-Parametros!$D$26-Parametros!$B$23-Parametros!$B$6-Parametros!$B$5-Parametros!$F$26)<=0,1000000000,MAX(Parametros!$B$26,(D12+Parametros!$E$26+Parametros!$B$24)/(1-Parametros!$D$26-Parametros!$B$23-Parametros!$B$6-Parametros!$B$5-Parametros!$F$26))) -> 68.666667 | O12: =IF((1-Parametros!$D$27-Parametros!$B$23-Parametros!$B$6-Parametros!$B$5-Parametros!$F$27)<=0,1000000000,MAX(Parametros!$B$27,(D12+Parametros!$E$27+Parametros!$B$24)/(1-Parametros!$D$27-Parametros!$B$23-Parametros!$B$6-Parametros!$B$5-Parametros!$F$27))) -> 14.5 | P12: =IF(Parametros!$B$8=1,CEILING(IF(N12<Parametros!$C$26,N12,O12)+0.1,1)-0.1,ROUNDUP(IF(N12<Parametros!$C$26,N12,O12),2)) -> 14.9 | Q12: =P12-P12*(INDEX(Parametros!$D$26:$D$27,MATCH(P12,Parametros!$B$26:$B$27,1))+Parametros!$B$23+Parametros!$B$6+INDEX(Parametros!$F$26:$F$27,MATCH(P12,Parametros!$B$26:$B$27,1)))-INDEX(Parametros!$E$26:$E$27,MATCH(P12,Parametros!$B$26:$B$27,1))-Parametros!$B$24-D12 -> 3.204 | R12: =Q12/P12 -> 0.21503356 | S12: =IF((1-Parametros!$D$33-Parametros!$B$30-Parametros!$B$6-Parametros!$B$5-Parametros!$F$33)<=0,1000000000,MAX(Parametros!$B$33,(D12+Parametros!$E$33+Parametros!$B$31)/(1-Parametros!$D$33-Parametros!$B$30-Parametros!$B$6-Parametros!$B$5-Parametros!$F$33))) -> 12.30303 | T12: =IF((1-Parametros!$D$34-Parametros!$B$30-Parametros!$B$6-Parametros!$B$5-Parametros!$F$34)<=0,1000000000,MAX(Parametros!$B$34,(D12+Parametros!$E$34+Parametros!$B$31)/(1-Parametros!$D$34-Parametros!$B$30-Parametros!$B$6-Parametros!$B$5-Parametros!$F$34))) -> 50 | U12: =IF(Parametros!$B$8=1,CEILING(IF(S12<Parametros!$C$33,S12,T12)+0.1,1)-0.1,ROUNDUP(IF(S12<Parametros!$C$33,S12,T12),2)) -> 12.9 | V12: =U12-U12*(INDEX(Parametros!$D$33:$D$34,MATCH(U12,Parametros!$B$33:$B$34,1))+Parametros!$B$30+Parametros!$B$6+INDEX(Parametros!$F$33:$F$34,MATCH(U12,Parametros!$B$33:$B$34,1)))-INDEX(Parametros!$E$33:$E$34,MATCH(U12,Parametros!$B$33:$B$34,1))-Parametros!$B$31-D12 -> 2.974 | W12: =V12/U12 -> 0.23054264 | X12: =IF(Parametros!$B$8=1,CEILING((D12+Parametros!$B$39)/(1-Parametros!$B$37-Parametros!$B$38-Parametros!$B$6-Parametros!$B$9)+0.1,1)-0.1,ROUNDUP((D12+Parametros!$B$39)/(1-Parametros!$B$37-Parametros!$B$38-Parametros!$B$6-Parametros!$B$9),2)) -> 9.9 | Y12: =X12-X12*(Parametros!$B$37+Parametros!$B$38+Parametros!$B$6)-Parametros!$B$39-D12 -> 5.384 | Z12: =Y12/X12 -> 0.54383838
A13: =Planilha1!A13 -> 10 | B13: =Planilha1!B13 -> Chaveiro Gato Bravo | C13: =Planilha1!C13 -> 2.49 | D13: =C13+Parametros!$B$7 -> 3.49 | E13: =IF(Parametros!$B$8=1,CEILING(D13/(1-Parametros!$B$9-Parametros!$B$6)+0.1,1)-0.1,ROUNDUP(D13/(1-Parametros!$B$9-Parametros!$B$6),2)) -> 7.9 | F13: =IF((1-Parametros!$D$15-Parametros!$B$12-Parametros!$B$6-Parametros!$B$5-Parametros!$F$15)<=0,1000000000,MAX(Parametros!$B$15,(D13+Parametros!$E$15+Parametros!$B$13)/(1-Parametros!$D$15-Parametros!$B$12-Parametros!$B$6-Parametros!$B$5-Parametros!$F$15))) -> 29.083333 | G13: =IF((1-Parametros!$D$16-Parametros!$B$12-Parametros!$B$6-Parametros!$B$5-Parametros!$F$16)<=0,1000000000,MAX(Parametros!$B$16,(D13+Parametros!$E$16+Parametros!$B$13)/(1-Parametros!$D$16-Parametros!$B$12-Parametros!$B$6-Parametros!$B$5-Parametros!$F$16))) -> 15.709677 | H13: =IF((1-Parametros!$D$17-Parametros!$B$12-Parametros!$B$6-Parametros!$B$5-Parametros!$F$17)<=0,1000000000,MAX(Parametros!$B$17,(D13+Parametros!$E$17+Parametros!$B$13)/(1-Parametros!$D$17-Parametros!$B$12-Parametros!$B$6-Parametros!$B$5-Parametros!$F$17))) -> 29 | I13: =IF((1-Parametros!$D$18-Parametros!$B$12-Parametros!$B$6-Parametros!$B$5-Parametros!$F$18)<=0,1000000000,MAX(Parametros!$B$18,(D13+Parametros!$E$18+Parametros!$B$13)/(1-Parametros!$D$18-Parametros!$B$12-Parametros!$B$6-Parametros!$B$5-Parametros!$F$18))) -> 50 | J13: =IF((1-Parametros!$D$19-Parametros!$B$12-Parametros!$B$6-Parametros!$B$5-Parametros!$F$19)<=0,1000000000,MAX(Parametros!$B$19,(D13+Parametros!$E$19+Parametros!$B$13)/(1-Parametros!$D$19-Parametros!$B$12-Parametros!$B$6-Parametros!$B$5-Parametros!$F$19))) -> 79 | K13: =IF(Parametros!$B$8=1,CEILING(IF(F13<Parametros!$C$15,F13,IF(G13<Parametros!$C$16,G13,IF(H13<Parametros!$C$17,H13,IF(I13<Parametros!$C$18,I13,J13))))+0.1,1)-0.1,ROUNDUP(IF(F13<Parametros!$C$15,F13,IF(G13<Parametros!$C$16,G13,IF(H13<Parametros!$C$17,H13,IF(I13<Parametros!$C$18,I13,J13)))),2)) -> 15.9 | L13: =K13-K13*(INDEX(Parametros!$D$15:$D$19,MATCH(K13,Parametros!$B$15:$B$19,1))+Parametros!$B$12+Parametros!$B$6+INDEX(Parametros!$F$15:$F$19,MATCH(K13,Parametros!$B$15:$B$19,1)))-INDEX(Parametros!$E$15:$E$19,MATCH(K13,Parametros!$B$15:$B$19,1))-Parametros!$B$13-D13 -> 3.298 | M13: =L13/K13 -> 0.20742138 | N13: =IF((1-Parametros!$D$26-Parametros!$B$23-Parametros!$B$6-Parametros!$B$5-Parametros!$F$26)<=0,1000000000,MAX(Parametros!$B$26,(D13+Parametros!$E$26+Parametros!$B$24)/(1-Parametros!$D$26-Parametros!$B$23-Parametros!$B$6-Parametros!$B$5-Parametros!$F$26))) -> 58.166667 | O13: =IF((1-Parametros!$D$27-Parametros!$B$23-Parametros!$B$6-Parametros!$B$5-Parametros!$F$27)<=0,1000000000,MAX(Parametros!$B$27,(D13+Parametros!$E$27+Parametros!$B$24)/(1-Parametros!$D$27-Parametros!$B$23-Parametros!$B$6-Parametros!$B$5-Parametros!$F$27))) -> 13.375 | P13: =IF(Parametros!$B$8=1,CEILING(IF(N13<Parametros!$C$26,N13,O13)+0.1,1)-0.1,ROUNDUP(IF(N13<Parametros!$C$26,N13,O13),2)) -> 13.9 | Q13: =P13-P13*(INDEX(Parametros!$D$26:$D$27,MATCH(P13,Parametros!$B$26:$B$27,1))+Parametros!$B$23+Parametros!$B$6+INDEX(Parametros!$F$26:$F$27,MATCH(P13,Parametros!$B$26:$B$27,1)))-INDEX(Parametros!$E$26:$E$27,MATCH(P13,Parametros!$B$26:$B$27,1))-Parametros!$B$24-D13 -> 3.074 | R13: =Q13/P13 -> 0.22115108 | S13: =IF((1-Parametros!$D$33-Parametros!$B$30-Parametros!$B$6-Parametros!$B$5-Parametros!$F$33)<=0,1000000000,MAX(Parametros!$B$33,(D13+Parametros!$E$33+Parametros!$B$31)/(1-Parametros!$D$33-Parametros!$B$30-Parametros!$B$6-Parametros!$B$5-Parametros!$F$33))) -> 11.348485 | T13: =IF((1-Parametros!$D$34-Parametros!$B$30-Parametros!$B$6-Parametros!$B$5-Parametros!$F$34)<=0,1000000000,MAX(Parametros!$B$34,(D13+Parametros!$E$34+Parametros!$B$31)/(1-Parametros!$D$34-Parametros!$B$30-Parametros!$B$6-Parametros!$B$5-Parametros!$F$34))) -> 50 | U13: =IF(Parametros!$B$8=1,CEILING(IF(S13<Parametros!$C$33,S13,T13)+0.1,1)-0.1,ROUNDUP(IF(S13<Parametros!$C$33,S13,T13),2)) -> 11.9 | V13: =U13-U13*(INDEX(Parametros!$D$33:$D$34,MATCH(U13,Parametros!$B$33:$B$34,1))+Parametros!$B$30+Parametros!$B$6+INDEX(Parametros!$F$33:$F$34,MATCH(U13,Parametros!$B$33:$B$34,1)))-INDEX(Parametros!$E$33:$E$34,MATCH(U13,Parametros!$B$33:$B$34,1))-Parametros!$B$31-D13 -> 2.744 | W13: =V13/U13 -> 0.23058824 | X13: =IF(Parametros!$B$8=1,CEILING((D13+Parametros!$B$39)/(1-Parametros!$B$37-Parametros!$B$38-Parametros!$B$6-Parametros!$B$9)+0.1,1)-0.1,ROUNDUP((D13+Parametros!$B$39)/(1-Parametros!$B$37-Parametros!$B$38-Parametros!$B$6-Parametros!$B$9),2)) -> 7.9 | Y13: =X13-X13*(Parametros!$B$37+Parametros!$B$38+Parametros!$B$6)-Parametros!$B$39-D13 -> 4.094 | Z13: =Y13/X13 -> 0.51822785
A14: =Planilha1!A14 -> 11 | B14: =Planilha1!B14 -> Chaveiro Patinha fofa | C14: =Planilha1!C14 -> 2.59 | D14: =C14+Parametros!$B$7 -> 3.59 | E14: =IF(Parametros!$B$8=1,CEILING(D14/(1-Parametros!$B$9-Parametros!$B$6)+0.1,1)-0.1,ROUNDUP(D14/(1-Parametros!$B$9-Parametros!$B$6),2)) -> 7.9 | F14: =IF((1-Parametros!$D$15-Parametros!$B$12-Parametros!$B$6-Parametros!$B$5-Parametros!$F$15)<=0,1000000000,MAX(Parametros!$B$15,(D14+Parametros!$E$15+Parametros!$B$13)/(1-Parametros!$D$15-Parametros!$B$12-Parametros!$B$6-Parametros!$B$5-Parametros!$F$15))) -> 29.916667 | G14: =IF((1-Parametros!$D$16-Parametros!$B$12-Parametros!$B$6-Parametros!$B$5-Parametros!$F$16)<=0,1000000000,MAX(Parametros!$B$16,(D14+Parametros!$E$16+Parametros!$B$13)/(1-Parametros!$D$16-Parametros!$B$12-Parametros!$B$6-Parametros!$B$5-Parametros!$F$16))) -> 15.870968 | H14: =IF((1-Parametros!$D$17-Parametros!$B$12-Parametros!$B$6-Parametros!$B$5-Parametros!$F$17)<=0,1000000000,MAX(Parametros!$B$17,(D14+Parametros!$E$17+Parametros!$B$13)/(1-Parametros!$D$17-Parametros!$B$12-Parametros!$B$6-Parametros!$B$5-Parametros!$F$17))) -> 29 | I14: =IF((1-Parametros!$D$18-Parametros!$B$12-Parametros!$B$6-Parametros!$B$5-Parametros!$F$18)<=0,1000000000,MAX(Parametros!$B$18,(D14+Parametros!$E$18+Parametros!$B$13)/(1-Parametros!$D$18-Parametros!$B$12-Parametros!$B$6-Parametros!$B$5-Parametros!$F$18))) -> 50 | J14: =IF((1-Parametros!$D$19-Parametros!$B$12-Parametros!$B$6-Parametros!$B$5-Parametros!$F$19)<=0,1000000000,MAX(Parametros!$B$19,(D14+Parametros!$E$19+Parametros!$B$13)/(1-Parametros!$D$19-Parametros!$B$12-Parametros!$B$6-Parametros!$B$5-Parametros!$F$19))) -> 79 | K14: =IF(Parametros!$B$8=1,CEILING(IF(F14<Parametros!$C$15,F14,IF(G14<Parametros!$C$16,G14,IF(H14<Parametros!$C$17,H14,IF(I14<Parametros!$C$18,I14,J14))))+0.1,1)-0.1,ROUNDUP(IF(F14<Parametros!$C$15,F14,IF(G14<Parametros!$C$16,G14,IF(H14<Parametros!$C$17,H14,IF(I14<Parametros!$C$18,I14,J14)))),2)) -> 15.9 | L14: =K14-K14*(INDEX(Parametros!$D$15:$D$19,MATCH(K14,Parametros!$B$15:$B$19,1))+Parametros!$B$12+Parametros!$B$6+INDEX(Parametros!$F$15:$F$19,MATCH(K14,Parametros!$B$15:$B$19,1)))-INDEX(Parametros!$E$15:$E$19,MATCH(K14,Parametros!$B$15:$B$19,1))-Parametros!$B$13-D14 -> 3.198 | M14: =L14/K14 -> 0.20113208 | N14: =IF((1-Parametros!$D$26-Parametros!$B$23-Parametros!$B$6-Parametros!$B$5-Parametros!$F$26)<=0,1000000000,MAX(Parametros!$B$26,(D14+Parametros!$E$26+Parametros!$B$24)/(1-Parametros!$D$26-Parametros!$B$23-Parametros!$B$6-Parametros!$B$5-Parametros!$F$26))) -> 59.833333 | O14: =IF((1-Parametros!$D$27-Parametros!$B$23-Parametros!$B$6-Parametros!$B$5-Parametros!$F$27)<=0,1000000000,MAX(Parametros!$B$27,(D14+Parametros!$E$27+Parametros!$B$24)/(1-Parametros!$D$27-Parametros!$B$23-Parametros!$B$6-Parametros!$B$5-Parametros!$F$27))) -> 13.553571 | P14: =IF(Parametros!$B$8=1,CEILING(IF(N14<Parametros!$C$26,N14,O14)+0.1,1)-0.1,ROUNDUP(IF(N14<Parametros!$C$26,N14,O14),2)) -> 13.9 | Q14: =P14-P14*(INDEX(Parametros!$D$26:$D$27,MATCH(P14,Parametros!$B$26:$B$27,1))+Parametros!$B$23+Parametros!$B$6+INDEX(Parametros!$F$26:$F$27,MATCH(P14,Parametros!$B$26:$B$27,1)))-INDEX(Parametros!$E$26:$E$27,MATCH(P14,Parametros!$B$26:$B$27,1))-Parametros!$B$24-D14 -> 2.974 | R14: =Q14/P14 -> 0.21395683 | S14: =IF((1-Parametros!$D$33-Parametros!$B$30-Parametros!$B$6-Parametros!$B$5-Parametros!$F$33)<=0,1000000000,MAX(Parametros!$B$33,(D14+Parametros!$E$33+Parametros!$B$31)/(1-Parametros!$D$33-Parametros!$B$30-Parametros!$B$6-Parametros!$B$5-Parametros!$F$33))) -> 11.5 | T14: =IF((1-Parametros!$D$34-Parametros!$B$30-Parametros!$B$6-Parametros!$B$5-Parametros!$F$34)<=0,1000000000,MAX(Parametros!$B$34,(D14+Parametros!$E$34+Parametros!$B$31)/(1-Parametros!$D$34-Parametros!$B$30-Parametros!$B$6-Parametros!$B$5-Parametros!$F$34))) -> 50 | U14: =IF(Parametros!$B$8=1,CEILING(IF(S14<Parametros!$C$33,S14,T14)+0.1,1)-0.1,ROUNDUP(IF(S14<Parametros!$C$33,S14,T14),2)) -> 11.9 | V14: =U14-U14*(INDEX(Parametros!$D$33:$D$34,MATCH(U14,Parametros!$B$33:$B$34,1))+Parametros!$B$30+Parametros!$B$6+INDEX(Parametros!$F$33:$F$34,MATCH(U14,Parametros!$B$33:$B$34,1)))-INDEX(Parametros!$E$33:$E$34,MATCH(U14,Parametros!$B$33:$B$34,1))-Parametros!$B$31-D14 -> 2.644 | W14: =V14/U14 -> 0.22218487 | X14: =IF(Parametros!$B$8=1,CEILING((D14+Parametros!$B$39)/(1-Parametros!$B$37-Parametros!$B$38-Parametros!$B$6-Parametros!$B$9)+0.1,1)-0.1,ROUNDUP((D14+Parametros!$B$39)/(1-Parametros!$B$37-Parametros!$B$38-Parametros!$B$6-Parametros!$B$9),2)) -> 7.9 | Y14: =X14-X14*(Parametros!$B$37+Parametros!$B$38+Parametros!$B$6)-Parametros!$B$39-D14 -> 3.994 | Z14: =Y14/X14 -> 0.50556962
